{
  "cells": [
    {
      "cell_type": "markdown",
      "metadata": {
        "id": "view-in-github",
        "colab_type": "text"
      },
      "source": [
        "<a href=\"https://colab.research.google.com/github/AshritaVaka/html-portfolio/blob/main/roi.ipynb\" target=\"_parent\"><img src=\"https://colab.research.google.com/assets/colab-badge.svg\" alt=\"Open In Colab\"/></a>"
      ]
    },
    {
      "cell_type": "code",
      "execution_count": null,
      "metadata": {
        "colab": {
          "base_uri": "https://localhost:8080/"
        },
        "id": "uomEJEqjhhhO",
        "outputId": "015cbb14-40af-4ab3-97bc-92cbad832a8b"
      },
      "outputs": [
        {
          "output_type": "stream",
          "name": "stdout",
          "text": [
            "Mounted at /gdrive\n"
          ]
        }
      ],
      "source": [
        "from google.colab import drive\n",
        "drive.mount('/gdrive')"
      ]
    },
    {
      "cell_type": "code",
      "execution_count": null,
      "metadata": {
        "id": "fspYskAQhUIU"
      },
      "outputs": [],
      "source": [
        "import cv2\n",
        "import numpy as np\n",
        "import matplotlib.pyplot as plt\n",
        "from skimage import io, color, exposure, morphology, measure\n",
        "from skimage import io, color, filters, segmentation, morphology\n",
        "from skimage.segmentation import active_contour\n",
        "import os\n",
        "import glob\n",
        "\n",
        "\n",
        "\n",
        "image_folder = \"/gdrive/MyDrive/Colab Notebooks/Data Set for Breast Cancer Patients/extracted images/imgext29_0\"\n",
        "output_folder = \"/gdrive/MyDrive/Colab Notebooks/Data Set for Breast Cancer Patients/roi/imgroi29_0\"\n",
        "\n",
        "i = 0\n",
        "\n",
        "os.makedirs(output_folder, exist_ok=True)\n",
        "\n",
        "# Iterate over all the images in the specified folder and extract the Haralick texture features\n",
        "for image_path in glob.glob(os.path.join(image_folder, \"*.png\")):\n",
        "  # Load histopathology image\n",
        "  image = io.imread(image_path)\n",
        "\n",
        "  # Function for preprocessing an image\n",
        "  def preprocess_image(image, target_size=(512, 512)):\n",
        "\n",
        "    # Ensure the image is in RGB format\n",
        "    if image.shape[2] == 4:\n",
        "        image = cv2.cvtColor(image, cv2.COLOR_RGBA2RGB)\n",
        "\n",
        "    # Resize the image for consistent analysis\n",
        "    resized_image = cv2.resize(image, target_size)\n",
        "\n",
        "    # Color normalization (Reinhard)\n",
        "    img_lab = cv2.cvtColor(resized_image, cv2.COLOR_RGB2LAB)\n",
        "    img_lab_planes = cv2.split(img_lab)\n",
        "\n",
        "    # Convert the tuple to a list so that we can modify it\n",
        "    img_lab_planes = list(img_lab_planes)\n",
        "\n",
        "    # Apply histogram equalization to the L channel\n",
        "    img_lab_planes[0] = cv2.equalizeHist(img_lab_planes[0])\n",
        "\n",
        "    # Merge the modified channels back to LAB format\n",
        "    img_lab_normalized = cv2.merge(img_lab_planes)\n",
        "    normalized_image = cv2.cvtColor(img_lab_normalized, cv2.COLOR_LAB2RGB)\n",
        "\n",
        "    # Convert to grayscale\n",
        "    grayscale_image = color.rgb2gray(normalized_image)\n",
        "\n",
        "    # Apply CLAHE (Contrast Limited Adaptive Histogram Equalization)\n",
        "    clahe = exposure.equalize_adapthist(grayscale_image, clip_limit=0.03)\n",
        "\n",
        "    # Apply Gaussian blur to reduce noise\n",
        "    blurred_image = cv2.GaussianBlur(clahe, (5, 5), 0)\n",
        "\n",
        "    return blurred_image\n",
        "\n",
        "  # Preprocess the image\n",
        "  preprocessed_image = preprocess_image(image)\n",
        "\n",
        "  # Display the preprocessed image\n",
        "  # plt.figure(figsize=(8, 8))\n",
        "  # plt.title('Preprocessed Image')\n",
        "  # plt.imshow(preprocessed_image, cmap='gray')\n",
        "  # plt.axis('off')\n",
        "  # plt.show()\n",
        "\n",
        "\n",
        "\n",
        "  # Save the preprocessed image as 'output.png'\n",
        "  output_path = 'output.png'\n",
        "  cv2.imwrite(output_path, (preprocessed_image * 255).astype(np.uint8))\n",
        "\n",
        "  print(f'Preprocessed image saved as {output_path}')\n",
        "\n",
        "  image_path = 'output.png'\n",
        "  gray_image = io.imread(image_path)\n",
        "\n",
        "  # Apply edge detection to find contours\n",
        "  edges = filters.sobel(gray_image)\n",
        "\n",
        "  # Perform morphological operations to enhance edges (optional)\n",
        "  selem = morphology.disk(2)\n",
        "  edges = morphology.closing(edges, selem)\n",
        "\n",
        "  # Initialize the contour using a rectangle or ellipse\n",
        "  # Replace these coordinates with the desired initial contour\n",
        "  # For example, for a rectangle, use [(x0, y0), (x1, y1), (x2, y2), (x3, y3)]\n",
        "  initial_contour = np.array([(100, 100), (400, 100), (400, 400), (100, 400)])\n",
        "\n",
        "  # Create an active contour model using GVF\n",
        "  snake = active_contour(edges, initial_contour, alpha=0.015, beta=10.0, gamma=0.001)\n",
        "\n",
        "  # Display the original image with the extracted ROI\n",
        "  # fig, ax = plt.subplots(figsize=(8, 8))\n",
        "  # ax.imshow(gray_image, cmap=plt.cm.gray)\n",
        "  # ax.plot(initial_contour[:, 0], initial_contour[:, 1], '--r', lw=3)\n",
        "  # ax.plot(snake[:, 0], snake[:, 1], '-b', lw=3)\n",
        "  # ax.set_xticks([]), ax.set_yticks([])\n",
        "  # ax.set_title('GVF Active Contour')\n",
        "\n",
        "  # Save the result as 'output2.png' in the local storage\n",
        "  output_path = 'output2.png'\n",
        "  plt.savefig(output_path, bbox_inches='tight', pad_inches=0, dpi=300)\n",
        "\n",
        "  # Show the result\n",
        "  #plt.show()\n",
        "\n",
        "  # Load the preprocessed image\n",
        "  image_path = 'output.png'\n",
        "  image = cv2.imread(image_path)\n",
        "\n",
        "  # Convert the image to LAB color space\n",
        "  lab_image = cv2.cvtColor(image, cv2.COLOR_BGR2LAB)\n",
        "\n",
        "  # Reshape the LAB image to a 2D array of pixels\n",
        "  pixels = lab_image.reshape((-1, 3))\n",
        "  pixels = np.float32(pixels)\n",
        "\n",
        "  # Define the number of clusters (e.g., 2 for ROI and background)\n",
        "  num_clusters = 2\n",
        "\n",
        "  # Perform k-means clustering\n",
        "  criteria = (cv2.TERM_CRITERIA_EPS + cv2.TERM_CRITERIA_MAX_ITER, 100, 0.2)\n",
        "  _, labels, centers = cv2.kmeans(pixels, num_clusters, None, criteria, 10, cv2.KMEANS_RANDOM_CENTERS)\n",
        "\n",
        "  # Reshape the labels to the shape of the original image\n",
        "  labels = labels.reshape(image.shape[:2])\n",
        "\n",
        "  # Assign the ROI label (cluster) based on the majority of pixels in the ROI\n",
        "  roi_label = 1 if np.sum(labels == 1) > np.sum(labels == 0) else 0\n",
        "\n",
        "  # Create a mask for the ROI\n",
        "  roi_mask = np.uint8(labels == roi_label)\n",
        "\n",
        "  # Extract the ROI from the original image using the mask\n",
        "  roi = cv2.bitwise_and(image, image, mask=roi_mask)\n",
        "\n",
        "  # Display the original image and the extracted ROI\n",
        "  # plt.figure(figsize=(12, 6))\n",
        "  # plt.subplot(121)\n",
        "  # plt.imshow(cv2.cvtColor(image, cv2.COLOR_BGR2RGB))\n",
        "  # plt.title('Original Image')\n",
        "  # plt.axis('off')\n",
        "\n",
        "  # plt.subplot(122)\n",
        "  # plt.imshow(cv2.cvtColor(roi, cv2.COLOR_BGR2RGB))\n",
        "  # plt.title('Extracted ROI')\n",
        "  # plt.axis('off')\n",
        "\n",
        "  plt.tight_layout()\n",
        "\n",
        "  # Save the extracted ROI as 'output3.png'\n",
        "  output_path = 'output3.png'\n",
        "  cv2.imwrite(output_path, roi)\n",
        "\n",
        "  print(f'Extracted ROI saved as {output_path}')\n",
        "\n",
        "  # Show the result\n",
        "  #plt.show()\n",
        "  output_image_path = os.path.join(output_folder, f\"image_{i}.png\")\n",
        "  cv2.imwrite(output_image_path, cv2.cvtColor(roi, cv2.COLOR_RGB2BGR))\n",
        "\n",
        "  i += 1\n",
        "\n",
        "print(\"done\")"
      ]
    },
    {
      "cell_type": "code",
      "execution_count": null,
      "metadata": {
        "colab": {
          "background_save": true
        },
        "id": "1zEsZSiyhmTU",
        "outputId": "474f2c84-0c5a-4c42-91fa-0c36ee1548d9"
      },
      "outputs": [
        {
          "name": "stderr",
          "output_type": "stream",
          "text": [
            "ERROR:root:Internal Python error in the inspect module.\n",
            "Below is the traceback from this internal error.\n",
            "\n",
            "ERROR:root:Internal Python error in the inspect module.\n",
            "Below is the traceback from this internal error.\n",
            "\n"
          ]
        },
        {
          "name": "stdout",
          "output_type": "stream",
          "text": [
            "Traceback (most recent call last):\n",
            "  File \"/usr/local/lib/python3.10/dist-packages/IPython/core/interactiveshell.py\", line 3553, in run_code\n",
            "    exec(code_obj, self.user_global_ns, self.user_ns)\n",
            "  File \"<ipython-input-13-a7c5d7188481>\", line 2, in <cell line: 2>\n",
            "    get_ipython().run_line_magic('cd', '/gdrive/My Drive/Colab Notebooks')\n",
            "  File \"/usr/local/lib/python3.10/dist-packages/IPython/core/interactiveshell.py\", line 2418, in run_line_magic\n",
            "    result = fn(*args, **kwargs)\n",
            "  File \"<decorator-gen-85>\", line 2, in cd\n",
            "  File \"/usr/local/lib/python3.10/dist-packages/IPython/core/magic.py\", line 187, in <lambda>\n",
            "    call = lambda f, *a, **k: f(*a, **k)\n",
            "  File \"/usr/local/lib/python3.10/dist-packages/IPython/core/magics/osm.py\", line 342, in cd\n",
            "    oldcwd = os.getcwd()\n",
            "OSError: [Errno 107] Transport endpoint is not connected\n",
            "\n",
            "During handling of the above exception, another exception occurred:\n",
            "\n",
            "Traceback (most recent call last):\n",
            "  File \"/usr/local/lib/python3.10/dist-packages/IPython/core/interactiveshell.py\", line 2099, in showtraceback\n",
            "    stb = value._render_traceback_()\n",
            "AttributeError: 'OSError' object has no attribute '_render_traceback_'\n",
            "\n",
            "During handling of the above exception, another exception occurred:\n",
            "\n",
            "Traceback (most recent call last):\n",
            "  File \"/usr/local/lib/python3.10/dist-packages/IPython/core/ultratb.py\", line 1101, in get_records\n",
            "    return _fixed_getinnerframes(etb, number_of_lines_of_context, tb_offset)\n",
            "  File \"/usr/local/lib/python3.10/dist-packages/IPython/core/ultratb.py\", line 248, in wrapped\n",
            "    return f(*args, **kwargs)\n",
            "  File \"/usr/local/lib/python3.10/dist-packages/IPython/core/ultratb.py\", line 281, in _fixed_getinnerframes\n",
            "    records = fix_frame_records_filenames(inspect.getinnerframes(etb, context))\n",
            "  File \"/usr/lib/python3.10/inspect.py\", line 1662, in getinnerframes\n",
            "    frameinfo = (tb.tb_frame,) + getframeinfo(tb, context)\n",
            "  File \"/usr/lib/python3.10/inspect.py\", line 1620, in getframeinfo\n",
            "    filename = getsourcefile(frame) or getfile(frame)\n",
            "  File \"/usr/lib/python3.10/inspect.py\", line 829, in getsourcefile\n",
            "    module = getmodule(object, filename)\n",
            "  File \"/usr/lib/python3.10/inspect.py\", line 861, in getmodule\n",
            "    file = getabsfile(object, _filename)\n",
            "  File \"/usr/lib/python3.10/inspect.py\", line 845, in getabsfile\n",
            "    return os.path.normcase(os.path.abspath(_filename))\n",
            "  File \"/usr/lib/python3.10/posixpath.py\", line 384, in abspath\n",
            "    cwd = os.getcwd()\n",
            "OSError: [Errno 107] Transport endpoint is not connected\n",
            "Traceback (most recent call last):\n",
            "  File \"/usr/local/lib/python3.10/dist-packages/IPython/core/interactiveshell.py\", line 3553, in run_code\n",
            "    exec(code_obj, self.user_global_ns, self.user_ns)\n",
            "  File \"<ipython-input-13-a7c5d7188481>\", line 2, in <cell line: 2>\n",
            "    get_ipython().run_line_magic('cd', '/gdrive/My Drive/Colab Notebooks')\n",
            "  File \"/usr/local/lib/python3.10/dist-packages/IPython/core/interactiveshell.py\", line 2418, in run_line_magic\n",
            "    result = fn(*args, **kwargs)\n",
            "  File \"<decorator-gen-85>\", line 2, in cd\n",
            "  File \"/usr/local/lib/python3.10/dist-packages/IPython/core/magic.py\", line 187, in <lambda>\n",
            "    call = lambda f, *a, **k: f(*a, **k)\n",
            "  File \"/usr/local/lib/python3.10/dist-packages/IPython/core/magics/osm.py\", line 342, in cd\n",
            "    oldcwd = os.getcwd()\n",
            "OSError: [Errno 107] Transport endpoint is not connected\n",
            "\n",
            "During handling of the above exception, another exception occurred:\n",
            "\n",
            "Traceback (most recent call last):\n",
            "  File \"/usr/local/lib/python3.10/dist-packages/IPython/core/interactiveshell.py\", line 2099, in showtraceback\n",
            "    stb = value._render_traceback_()\n",
            "AttributeError: 'OSError' object has no attribute '_render_traceback_'\n",
            "\n",
            "During handling of the above exception, another exception occurred:\n",
            "\n",
            "Traceback (most recent call last):\n",
            "  File \"/usr/local/lib/python3.10/dist-packages/IPython/core/interactiveshell.py\", line 3473, in run_ast_nodes\n",
            "    if (await self.run_code(code, result,  async_=asy)):\n",
            "  File \"/usr/local/lib/python3.10/dist-packages/IPython/core/interactiveshell.py\", line 3575, in run_code\n",
            "    self.showtraceback(running_compiled_code=True)\n",
            "  File \"/usr/local/lib/python3.10/dist-packages/IPython/core/interactiveshell.py\", line 2101, in showtraceback\n",
            "    stb = self.InteractiveTB.structured_traceback(etype,\n",
            "  File \"/usr/local/lib/python3.10/dist-packages/IPython/core/ultratb.py\", line 1367, in structured_traceback\n",
            "    return FormattedTB.structured_traceback(\n",
            "  File \"/usr/local/lib/python3.10/dist-packages/IPython/core/ultratb.py\", line 1267, in structured_traceback\n",
            "    return VerboseTB.structured_traceback(\n",
            "  File \"/usr/local/lib/python3.10/dist-packages/IPython/core/ultratb.py\", line 1124, in structured_traceback\n",
            "    formatted_exception = self.format_exception_as_a_whole(etype, evalue, etb, number_of_lines_of_context,\n",
            "  File \"/usr/local/lib/python3.10/dist-packages/IPython/core/ultratb.py\", line 1082, in format_exception_as_a_whole\n",
            "    last_unique, recursion_repeat = find_recursion(orig_etype, evalue, records)\n",
            "  File \"/usr/local/lib/python3.10/dist-packages/IPython/core/ultratb.py\", line 382, in find_recursion\n",
            "    return len(records), 0\n",
            "TypeError: object of type 'NoneType' has no len()\n",
            "\n",
            "During handling of the above exception, another exception occurred:\n",
            "\n",
            "Traceback (most recent call last):\n",
            "  File \"/usr/local/lib/python3.10/dist-packages/IPython/core/interactiveshell.py\", line 2099, in showtraceback\n",
            "    stb = value._render_traceback_()\n",
            "AttributeError: 'TypeError' object has no attribute '_render_traceback_'\n",
            "\n",
            "During handling of the above exception, another exception occurred:\n",
            "\n",
            "Traceback (most recent call last):\n",
            "  File \"/usr/local/lib/python3.10/dist-packages/IPython/core/ultratb.py\", line 1101, in get_records\n",
            "    return _fixed_getinnerframes(etb, number_of_lines_of_context, tb_offset)\n",
            "  File \"/usr/local/lib/python3.10/dist-packages/IPython/core/ultratb.py\", line 248, in wrapped\n",
            "    return f(*args, **kwargs)\n",
            "  File \"/usr/local/lib/python3.10/dist-packages/IPython/core/ultratb.py\", line 281, in _fixed_getinnerframes\n",
            "    records = fix_frame_records_filenames(inspect.getinnerframes(etb, context))\n",
            "  File \"/usr/lib/python3.10/inspect.py\", line 1662, in getinnerframes\n",
            "    frameinfo = (tb.tb_frame,) + getframeinfo(tb, context)\n",
            "  File \"/usr/lib/python3.10/inspect.py\", line 1620, in getframeinfo\n",
            "    filename = getsourcefile(frame) or getfile(frame)\n",
            "  File \"/usr/lib/python3.10/inspect.py\", line 829, in getsourcefile\n",
            "    module = getmodule(object, filename)\n",
            "  File \"/usr/lib/python3.10/inspect.py\", line 861, in getmodule\n",
            "    file = getabsfile(object, _filename)\n",
            "  File \"/usr/lib/python3.10/inspect.py\", line 845, in getabsfile\n",
            "    return os.path.normcase(os.path.abspath(_filename))\n",
            "  File \"/usr/lib/python3.10/posixpath.py\", line 384, in abspath\n",
            "    cwd = os.getcwd()\n",
            "OSError: [Errno 107] Transport endpoint is not connected\n"
          ]
        },
        {
          "name": "stderr",
          "output_type": "stream",
          "text": [
            "ERROR:root:Internal Python error in the inspect module.\n",
            "Below is the traceback from this internal error.\n",
            "\n"
          ]
        },
        {
          "name": "stdout",
          "output_type": "stream",
          "text": [
            "Traceback (most recent call last):\n",
            "  File \"/usr/local/lib/python3.10/dist-packages/IPython/core/interactiveshell.py\", line 3553, in run_code\n",
            "    exec(code_obj, self.user_global_ns, self.user_ns)\n",
            "  File \"<ipython-input-13-a7c5d7188481>\", line 2, in <cell line: 2>\n",
            "    get_ipython().run_line_magic('cd', '/gdrive/My Drive/Colab Notebooks')\n",
            "  File \"/usr/local/lib/python3.10/dist-packages/IPython/core/interactiveshell.py\", line 2418, in run_line_magic\n",
            "    result = fn(*args, **kwargs)\n",
            "  File \"<decorator-gen-85>\", line 2, in cd\n",
            "  File \"/usr/local/lib/python3.10/dist-packages/IPython/core/magic.py\", line 187, in <lambda>\n",
            "    call = lambda f, *a, **k: f(*a, **k)\n",
            "  File \"/usr/local/lib/python3.10/dist-packages/IPython/core/magics/osm.py\", line 342, in cd\n",
            "    oldcwd = os.getcwd()\n",
            "OSError: [Errno 107] Transport endpoint is not connected\n",
            "\n",
            "During handling of the above exception, another exception occurred:\n",
            "\n",
            "Traceback (most recent call last):\n",
            "  File \"/usr/local/lib/python3.10/dist-packages/IPython/core/interactiveshell.py\", line 2099, in showtraceback\n",
            "    stb = value._render_traceback_()\n",
            "AttributeError: 'OSError' object has no attribute '_render_traceback_'\n",
            "\n",
            "During handling of the above exception, another exception occurred:\n",
            "\n",
            "Traceback (most recent call last):\n",
            "  File \"/usr/local/lib/python3.10/dist-packages/IPython/core/interactiveshell.py\", line 3473, in run_ast_nodes\n",
            "    if (await self.run_code(code, result,  async_=asy)):\n",
            "  File \"/usr/local/lib/python3.10/dist-packages/IPython/core/interactiveshell.py\", line 3575, in run_code\n",
            "    self.showtraceback(running_compiled_code=True)\n",
            "  File \"/usr/local/lib/python3.10/dist-packages/IPython/core/interactiveshell.py\", line 2101, in showtraceback\n",
            "    stb = self.InteractiveTB.structured_traceback(etype,\n",
            "  File \"/usr/local/lib/python3.10/dist-packages/IPython/core/ultratb.py\", line 1367, in structured_traceback\n",
            "    return FormattedTB.structured_traceback(\n",
            "  File \"/usr/local/lib/python3.10/dist-packages/IPython/core/ultratb.py\", line 1267, in structured_traceback\n",
            "    return VerboseTB.structured_traceback(\n",
            "  File \"/usr/local/lib/python3.10/dist-packages/IPython/core/ultratb.py\", line 1124, in structured_traceback\n",
            "    formatted_exception = self.format_exception_as_a_whole(etype, evalue, etb, number_of_lines_of_context,\n",
            "  File \"/usr/local/lib/python3.10/dist-packages/IPython/core/ultratb.py\", line 1082, in format_exception_as_a_whole\n",
            "    last_unique, recursion_repeat = find_recursion(orig_etype, evalue, records)\n",
            "  File \"/usr/local/lib/python3.10/dist-packages/IPython/core/ultratb.py\", line 382, in find_recursion\n",
            "    return len(records), 0\n",
            "TypeError: object of type 'NoneType' has no len()\n",
            "\n",
            "During handling of the above exception, another exception occurred:\n",
            "\n",
            "Traceback (most recent call last):\n",
            "  File \"/usr/local/lib/python3.10/dist-packages/IPython/core/interactiveshell.py\", line 2099, in showtraceback\n",
            "    stb = value._render_traceback_()\n",
            "AttributeError: 'TypeError' object has no attribute '_render_traceback_'\n",
            "\n",
            "During handling of the above exception, another exception occurred:\n",
            "\n",
            "Traceback (most recent call last):\n",
            "  File \"/usr/local/lib/python3.10/dist-packages/IPython/core/interactiveshell.py\", line 3030, in _run_cell\n",
            "    return runner(coro)\n",
            "  File \"/usr/local/lib/python3.10/dist-packages/IPython/core/async_helpers.py\", line 78, in _pseudo_sync_runner\n",
            "    coro.send(None)\n",
            "  File \"/usr/local/lib/python3.10/dist-packages/IPython/core/interactiveshell.py\", line 3257, in run_cell_async\n",
            "    has_raised = await self.run_ast_nodes(code_ast.body, cell_name,\n",
            "  File \"/usr/local/lib/python3.10/dist-packages/IPython/core/interactiveshell.py\", line 3492, in run_ast_nodes\n",
            "    self.showtraceback()\n",
            "  File \"/usr/local/lib/python3.10/dist-packages/IPython/core/interactiveshell.py\", line 2101, in showtraceback\n",
            "    stb = self.InteractiveTB.structured_traceback(etype,\n",
            "  File \"/usr/local/lib/python3.10/dist-packages/IPython/core/ultratb.py\", line 1367, in structured_traceback\n",
            "    return FormattedTB.structured_traceback(\n",
            "  File \"/usr/local/lib/python3.10/dist-packages/IPython/core/ultratb.py\", line 1267, in structured_traceback\n",
            "    return VerboseTB.structured_traceback(\n",
            "  File \"/usr/local/lib/python3.10/dist-packages/IPython/core/ultratb.py\", line 1142, in structured_traceback\n",
            "    formatted_exceptions += self.format_exception_as_a_whole(etype, evalue, etb, lines_of_context,\n",
            "  File \"/usr/local/lib/python3.10/dist-packages/IPython/core/ultratb.py\", line 1082, in format_exception_as_a_whole\n",
            "    last_unique, recursion_repeat = find_recursion(orig_etype, evalue, records)\n",
            "  File \"/usr/local/lib/python3.10/dist-packages/IPython/core/ultratb.py\", line 382, in find_recursion\n",
            "    return len(records), 0\n",
            "TypeError: object of type 'NoneType' has no len()\n",
            "\n",
            "During handling of the above exception, another exception occurred:\n",
            "\n",
            "Traceback (most recent call last):\n",
            "  File \"/usr/local/lib/python3.10/dist-packages/IPython/core/interactiveshell.py\", line 2099, in showtraceback\n",
            "    stb = value._render_traceback_()\n",
            "AttributeError: 'TypeError' object has no attribute '_render_traceback_'\n",
            "\n",
            "During handling of the above exception, another exception occurred:\n",
            "\n",
            "Traceback (most recent call last):\n",
            "  File \"/usr/local/lib/python3.10/dist-packages/IPython/core/ultratb.py\", line 1101, in get_records\n",
            "    return _fixed_getinnerframes(etb, number_of_lines_of_context, tb_offset)\n",
            "  File \"/usr/local/lib/python3.10/dist-packages/IPython/core/ultratb.py\", line 248, in wrapped\n",
            "    return f(*args, **kwargs)\n",
            "  File \"/usr/local/lib/python3.10/dist-packages/IPython/core/ultratb.py\", line 281, in _fixed_getinnerframes\n",
            "    records = fix_frame_records_filenames(inspect.getinnerframes(etb, context))\n",
            "  File \"/usr/lib/python3.10/inspect.py\", line 1662, in getinnerframes\n",
            "    frameinfo = (tb.tb_frame,) + getframeinfo(tb, context)\n",
            "  File \"/usr/lib/python3.10/inspect.py\", line 1620, in getframeinfo\n",
            "    filename = getsourcefile(frame) or getfile(frame)\n",
            "  File \"/usr/lib/python3.10/inspect.py\", line 829, in getsourcefile\n",
            "    module = getmodule(object, filename)\n",
            "  File \"/usr/lib/python3.10/inspect.py\", line 861, in getmodule\n",
            "    file = getabsfile(object, _filename)\n",
            "  File \"/usr/lib/python3.10/inspect.py\", line 845, in getabsfile\n",
            "    return os.path.normcase(os.path.abspath(_filename))\n",
            "  File \"/usr/lib/python3.10/posixpath.py\", line 384, in abspath\n",
            "    cwd = os.getcwd()\n",
            "OSError: [Errno 107] Transport endpoint is not connected\n"
          ]
        }
      ],
      "source": [
        "#path that contains folder you want to copy\n",
        "%cd /gdrive/My Drive/Colab Notebooks\n",
        "%cp -av /gdrive/MyDrive/Colab Notebooks/roi/ imgroi"
      ]
    }
  ],
  "metadata": {
    "colab": {
      "provenance": [],
      "include_colab_link": true
    },
    "kernelspec": {
      "display_name": "Python 3",
      "name": "python3"
    },
    "language_info": {
      "name": "python"
    }
  },
  "nbformat": 4,
  "nbformat_minor": 0
}